<robot name="simple">

    <link name="world"/>
    <link name="tool">
        <visual>
            <origin xyz="0 0 0.5" rpy="0 0 0"/>
            <geometry>
                <box size="0.1 0.1 1"/>
            </geometry>
        </visual>
    </link>

    <joint name="q1" type="revolute">
        <origin xyz="0 0 1" rpy=" 0 0 0"/>
        <parent link="world"/>
        <child link="tool"/>

        <axis xyz="0 0 1"/>
        <limit lower="-1" upper="1" effort="1" velocity="1"/>
    </joint>

    
</robot>
